[2023-04-26T20:13:23.731+0000] {taskinstance.py:1090} INFO - Dependencies all met for dep_context=non-requeueable deps ti=<TaskInstance: chatgpt_dag.chatgpt_request manual__2023-04-26T20:13:21.990733+00:00 [queued]>
[2023-04-26T20:13:23.735+0000] {taskinstance.py:1090} INFO - Dependencies all met for dep_context=requeueable deps ti=<TaskInstance: chatgpt_dag.chatgpt_request manual__2023-04-26T20:13:21.990733+00:00 [queued]>
[2023-04-26T20:13:23.735+0000] {taskinstance.py:1288} INFO - 
--------------------------------------------------------------------------------
[2023-04-26T20:13:23.735+0000] {taskinstance.py:1289} INFO - Starting attempt 1 of 1
[2023-04-26T20:13:23.735+0000] {taskinstance.py:1290} INFO - 
--------------------------------------------------------------------------------
[2023-04-26T20:13:23.745+0000] {taskinstance.py:1309} INFO - Executing <Task(PythonOperator): chatgpt_request> on 2023-04-26 20:13:21.990733+00:00
[2023-04-26T20:13:23.747+0000] {standard_task_runner.py:55} INFO - Started process 22583 to run task
[2023-04-26T20:13:23.749+0000] {standard_task_runner.py:82} INFO - Running: ['airflow', 'tasks', 'run', 'chatgpt_dag', 'chatgpt_request', 'manual__2023-04-26T20:13:21.990733+00:00', '--job-id', '114', '--raw', '--subdir', 'DAGS_FOLDER/chatgpt_dag.py', '--cfg-path', '/tmp/tmpli1sg5lm']
[2023-04-26T20:13:23.750+0000] {standard_task_runner.py:83} INFO - Job 114: Subtask chatgpt_request
[2023-04-26T20:13:23.777+0000] {task_command.py:389} INFO - Running <TaskInstance: chatgpt_dag.chatgpt_request manual__2023-04-26T20:13:21.990733+00:00 [running]> on host trivia-machine.us-central1-a.c.triviapractice-381517.internal
[2023-04-26T20:13:23.808+0000] {taskinstance.py:1516} INFO - Exporting the following env vars:
AIRFLOW_CTX_DAG_OWNER=richc
AIRFLOW_CTX_DAG_ID=chatgpt_dag
AIRFLOW_CTX_TASK_ID=chatgpt_request
AIRFLOW_CTX_EXECUTION_DATE=2023-04-26T20:13:21.990733+00:00
AIRFLOW_CTX_TRY_NUMBER=1
AIRFLOW_CTX_DAG_RUN_ID=manual__2023-04-26T20:13:21.990733+00:00
[2023-04-26T20:13:23.932+0000] {util.py:67} INFO - error_code=invalid_api_key error_message="Incorrect API key provided: ('sk-Rum********************************************r',). You can find your API key at https://platform.openai.com/account/api-keys." error_param=None error_type=invalid_request_error message='OpenAI API error received' stream_error=False
[2023-04-26T20:13:23.932+0000] {taskinstance.py:1776} ERROR - Task failed with exception
Traceback (most recent call last):
  File "/usr/local/lib/python3.9/dist-packages/airflow/operators/python.py", line 175, in execute
    return_value = self.execute_callable()
  File "/usr/local/lib/python3.9/dist-packages/airflow/operators/python.py", line 192, in execute_callable
    return self.python_callable(*self.op_args, **self.op_kwargs)
  File "/home/rich2/airflow/dags/chatgpt_dag.py", line 40, in chatgpt_request
    response = openai.Completion.create(
  File "/home/rich2/.local/lib/python3.9/site-packages/openai/api_resources/completion.py", line 25, in create
    return super().create(*args, **kwargs)
  File "/home/rich2/.local/lib/python3.9/site-packages/openai/api_resources/abstract/engine_api_resource.py", line 153, in create
    response, _, api_key = requestor.request(
  File "/home/rich2/.local/lib/python3.9/site-packages/openai/api_requestor.py", line 226, in request
    resp, got_stream = self._interpret_response(result, stream)
  File "/home/rich2/.local/lib/python3.9/site-packages/openai/api_requestor.py", line 620, in _interpret_response
    self._interpret_response_line(
  File "/home/rich2/.local/lib/python3.9/site-packages/openai/api_requestor.py", line 683, in _interpret_response_line
    raise self.handle_error_response(
openai.error.AuthenticationError: Incorrect API key provided: ('sk-Rum********************************************r',). You can find your API key at https://platform.openai.com/account/api-keys.
[2023-04-26T20:13:23.936+0000] {taskinstance.py:1327} INFO - Marking task as FAILED. dag_id=chatgpt_dag, task_id=chatgpt_request, execution_date=20230426T201321, start_date=20230426T201323, end_date=20230426T201323
[2023-04-26T20:13:23.945+0000] {standard_task_runner.py:100} ERROR - Failed to execute job 114 for task chatgpt_request (Incorrect API key provided: ('sk-Rum********************************************r',). You can find your API key at https://platform.openai.com/account/api-keys.; 22583)
[2023-04-26T20:13:23.961+0000] {local_task_job.py:212} INFO - Task exited with return code 1
[2023-04-26T20:13:23.972+0000] {taskinstance.py:2596} INFO - 0 downstream tasks scheduled from follow-on schedule check
