[2023-04-26T20:21:33.301+0000] {taskinstance.py:1090} INFO - Dependencies all met for dep_context=non-requeueable deps ti=<TaskInstance: chatgpt_dag.chatgpt_saveresponse manual__2023-04-26T20:21:21.433163+00:00 [queued]>
[2023-04-26T20:21:33.305+0000] {taskinstance.py:1090} INFO - Dependencies all met for dep_context=requeueable deps ti=<TaskInstance: chatgpt_dag.chatgpt_saveresponse manual__2023-04-26T20:21:21.433163+00:00 [queued]>
[2023-04-26T20:21:33.305+0000] {taskinstance.py:1288} INFO - 
--------------------------------------------------------------------------------
[2023-04-26T20:21:33.305+0000] {taskinstance.py:1289} INFO - Starting attempt 1 of 1
[2023-04-26T20:21:33.305+0000] {taskinstance.py:1290} INFO - 
--------------------------------------------------------------------------------
[2023-04-26T20:21:33.315+0000] {taskinstance.py:1309} INFO - Executing <Task(PythonOperator): chatgpt_saveresponse> on 2023-04-26 20:21:21.433163+00:00
[2023-04-26T20:21:33.318+0000] {standard_task_runner.py:55} INFO - Started process 24410 to run task
[2023-04-26T20:21:33.320+0000] {standard_task_runner.py:82} INFO - Running: ['airflow', 'tasks', 'run', 'chatgpt_dag', 'chatgpt_saveresponse', 'manual__2023-04-26T20:21:21.433163+00:00', '--job-id', '118', '--raw', '--subdir', 'DAGS_FOLDER/chatgpt_dag.py', '--cfg-path', '/tmp/tmp02iu1h_m']
[2023-04-26T20:21:33.320+0000] {standard_task_runner.py:83} INFO - Job 118: Subtask chatgpt_saveresponse
[2023-04-26T20:21:33.349+0000] {task_command.py:389} INFO - Running <TaskInstance: chatgpt_dag.chatgpt_saveresponse manual__2023-04-26T20:21:21.433163+00:00 [running]> on host trivia-machine.us-central1-a.c.triviapractice-381517.internal
[2023-04-26T20:21:33.380+0000] {taskinstance.py:1516} INFO - Exporting the following env vars:
AIRFLOW_CTX_DAG_OWNER=richc
AIRFLOW_CTX_DAG_ID=chatgpt_dag
AIRFLOW_CTX_TASK_ID=chatgpt_saveresponse
AIRFLOW_CTX_EXECUTION_DATE=2023-04-26T20:21:21.433163+00:00
AIRFLOW_CTX_TRY_NUMBER=1
AIRFLOW_CTX_DAG_RUN_ID=manual__2023-04-26T20:21:21.433163+00:00
[2023-04-26T20:21:33.385+0000] {taskinstance.py:1776} ERROR - Task failed with exception
Traceback (most recent call last):
  File "/usr/local/lib/python3.9/dist-packages/airflow/operators/python.py", line 175, in execute
    return_value = self.execute_callable()
  File "/usr/local/lib/python3.9/dist-packages/airflow/operators/python.py", line 192, in execute_callable
    return self.python_callable(*self.op_args, **self.op_kwargs)
  File "/home/rich2/airflow/dags/chatgpt_dag.py", line 53, in save_response
    category_text = chatgpt_response["random_category"].replace(' ','').lower()
KeyError: 'random_category'
[2023-04-26T20:21:33.387+0000] {taskinstance.py:1327} INFO - Marking task as FAILED. dag_id=chatgpt_dag, task_id=chatgpt_saveresponse, execution_date=20230426T202121, start_date=20230426T202133, end_date=20230426T202133
[2023-04-26T20:21:33.395+0000] {standard_task_runner.py:100} ERROR - Failed to execute job 118 for task chatgpt_saveresponse ('random_category'; 24410)
[2023-04-26T20:21:33.411+0000] {local_task_job.py:212} INFO - Task exited with return code 1
[2023-04-26T20:21:33.419+0000] {taskinstance.py:2596} INFO - 0 downstream tasks scheduled from follow-on schedule check
