[2023-04-26T20:16:46.560+0000] {taskinstance.py:1090} INFO - Dependencies all met for dep_context=non-requeueable deps ti=<TaskInstance: chatgpt_dag.chatgpt_saveresponse manual__2023-04-26T20:16:35.348972+00:00 [queued]>
[2023-04-26T20:16:46.564+0000] {taskinstance.py:1090} INFO - Dependencies all met for dep_context=requeueable deps ti=<TaskInstance: chatgpt_dag.chatgpt_saveresponse manual__2023-04-26T20:16:35.348972+00:00 [queued]>
[2023-04-26T20:16:46.564+0000] {taskinstance.py:1288} INFO - 
--------------------------------------------------------------------------------
[2023-04-26T20:16:46.564+0000] {taskinstance.py:1289} INFO - Starting attempt 1 of 1
[2023-04-26T20:16:46.564+0000] {taskinstance.py:1290} INFO - 
--------------------------------------------------------------------------------
[2023-04-26T20:16:46.574+0000] {taskinstance.py:1309} INFO - Executing <Task(PythonOperator): chatgpt_saveresponse> on 2023-04-26 20:16:35.348972+00:00
[2023-04-26T20:16:46.577+0000] {standard_task_runner.py:55} INFO - Started process 23436 to run task
[2023-04-26T20:16:46.579+0000] {standard_task_runner.py:82} INFO - Running: ['airflow', 'tasks', 'run', 'chatgpt_dag', 'chatgpt_saveresponse', 'manual__2023-04-26T20:16:35.348972+00:00', '--job-id', '116', '--raw', '--subdir', 'DAGS_FOLDER/chatgpt_dag.py', '--cfg-path', '/tmp/tmp80qh9h_b']
[2023-04-26T20:16:46.579+0000] {standard_task_runner.py:83} INFO - Job 116: Subtask chatgpt_saveresponse
[2023-04-26T20:16:46.607+0000] {task_command.py:389} INFO - Running <TaskInstance: chatgpt_dag.chatgpt_saveresponse manual__2023-04-26T20:16:35.348972+00:00 [running]> on host trivia-machine.us-central1-a.c.triviapractice-381517.internal
[2023-04-26T20:16:46.639+0000] {taskinstance.py:1516} INFO - Exporting the following env vars:
AIRFLOW_CTX_DAG_OWNER=richc
AIRFLOW_CTX_DAG_ID=chatgpt_dag
AIRFLOW_CTX_TASK_ID=chatgpt_saveresponse
AIRFLOW_CTX_EXECUTION_DATE=2023-04-26T20:16:35.348972+00:00
AIRFLOW_CTX_TRY_NUMBER=1
AIRFLOW_CTX_DAG_RUN_ID=manual__2023-04-26T20:16:35.348972+00:00
[2023-04-26T20:16:46.643+0000] {taskinstance.py:1776} ERROR - Task failed with exception
Traceback (most recent call last):
  File "/usr/local/lib/python3.9/dist-packages/airflow/operators/python.py", line 175, in execute
    return_value = self.execute_callable()
  File "/usr/local/lib/python3.9/dist-packages/airflow/operators/python.py", line 192, in execute_callable
    return self.python_callable(*self.op_args, **self.op_kwargs)
  File "/home/rich2/airflow/dags/chatgpt_dag.py", line 53, in save_response
    category_text = random_category.replace(' ','').lower()
NameError: name 'random_category' is not defined
[2023-04-26T20:16:46.645+0000] {taskinstance.py:1327} INFO - Marking task as FAILED. dag_id=chatgpt_dag, task_id=chatgpt_saveresponse, execution_date=20230426T201635, start_date=20230426T201646, end_date=20230426T201646
[2023-04-26T20:16:46.653+0000] {standard_task_runner.py:100} ERROR - Failed to execute job 116 for task chatgpt_saveresponse (name 'random_category' is not defined; 23436)
[2023-04-26T20:16:46.670+0000] {local_task_job.py:212} INFO - Task exited with return code 1
[2023-04-26T20:16:46.678+0000] {taskinstance.py:2596} INFO - 0 downstream tasks scheduled from follow-on schedule check
