[2023-05-03T19:41:40.812+0000] {taskinstance.py:1090} INFO - Dependencies all met for dep_context=non-requeueable deps ti=<TaskInstance: etl_dag.extract_data_gcp manual__2023-05-03T19:41:36.842453+00:00 [queued]>
[2023-05-03T19:41:40.816+0000] {taskinstance.py:1090} INFO - Dependencies all met for dep_context=requeueable deps ti=<TaskInstance: etl_dag.extract_data_gcp manual__2023-05-03T19:41:36.842453+00:00 [queued]>
[2023-05-03T19:41:40.816+0000] {taskinstance.py:1288} INFO - 
--------------------------------------------------------------------------------
[2023-05-03T19:41:40.817+0000] {taskinstance.py:1289} INFO - Starting attempt 1 of 1
[2023-05-03T19:41:40.817+0000] {taskinstance.py:1290} INFO - 
--------------------------------------------------------------------------------
[2023-05-03T19:41:40.826+0000] {taskinstance.py:1309} INFO - Executing <Task(PythonOperator): extract_data_gcp> on 2023-05-03 19:41:36.842453+00:00
[2023-05-03T19:41:40.829+0000] {standard_task_runner.py:55} INFO - Started process 225679 to run task
[2023-05-03T19:41:40.831+0000] {standard_task_runner.py:82} INFO - Running: ['airflow', 'tasks', 'run', 'etl_dag', 'extract_data_gcp', 'manual__2023-05-03T19:41:36.842453+00:00', '--job-id', '2711', '--raw', '--subdir', 'DAGS_FOLDER/etl_dag.py', '--cfg-path', '/tmp/tmp5m_wq25g']
[2023-05-03T19:41:40.831+0000] {standard_task_runner.py:83} INFO - Job 2711: Subtask extract_data_gcp
[2023-05-03T19:41:40.857+0000] {task_command.py:389} INFO - Running <TaskInstance: etl_dag.extract_data_gcp manual__2023-05-03T19:41:36.842453+00:00 [running]> on host trivia-machine.us-central1-a.c.triviapractice-381517.internal
[2023-05-03T19:41:40.891+0000] {taskinstance.py:1516} INFO - Exporting the following env vars:
AIRFLOW_CTX_DAG_OWNER=richc
AIRFLOW_CTX_DAG_ID=etl_dag
AIRFLOW_CTX_TASK_ID=extract_data_gcp
AIRFLOW_CTX_EXECUTION_DATE=2023-05-03T19:41:36.842453+00:00
AIRFLOW_CTX_TRY_NUMBER=1
AIRFLOW_CTX_DAG_RUN_ID=manual__2023-05-03T19:41:36.842453+00:00
[2023-05-03T19:41:40.892+0000] {taskinstance.py:1776} ERROR - Task failed with exception
Traceback (most recent call last):
  File "/usr/local/lib/python3.9/dist-packages/airflow/operators/python.py", line 175, in execute
    return_value = self.execute_callable()
  File "/usr/local/lib/python3.9/dist-packages/airflow/operators/python.py", line 192, in execute_callable
    return self.python_callable(*self.op_args, **self.op_kwargs)
  File "/home/rich2/airflow/dags/etl_dag.py", line 35, in extract_data_gcp
    bucket = storage_client.get_bucket(bucket_name)
NameError: name 'storage_client' is not defined
[2023-05-03T19:41:40.894+0000] {taskinstance.py:1327} INFO - Marking task as FAILED. dag_id=etl_dag, task_id=extract_data_gcp, execution_date=20230503T194136, start_date=20230503T194140, end_date=20230503T194140
[2023-05-03T19:41:40.902+0000] {standard_task_runner.py:100} ERROR - Failed to execute job 2711 for task extract_data_gcp (name 'storage_client' is not defined; 225679)
[2023-05-03T19:41:40.922+0000] {local_task_job.py:212} INFO - Task exited with return code 1
[2023-05-03T19:41:40.933+0000] {taskinstance.py:2596} INFO - 0 downstream tasks scheduled from follow-on schedule check
