[2023-05-03T11:50:02.646+0000] {taskinstance.py:1090} INFO - Dependencies all met for dep_context=non-requeueable deps ti=<TaskInstance: chatgpt_dag.chatgpt_request scheduled__2023-05-03T11:45:00+00:00 [queued]>
[2023-05-03T11:50:02.650+0000] {taskinstance.py:1090} INFO - Dependencies all met for dep_context=requeueable deps ti=<TaskInstance: chatgpt_dag.chatgpt_request scheduled__2023-05-03T11:45:00+00:00 [queued]>
[2023-05-03T11:50:02.650+0000] {taskinstance.py:1288} INFO - 
--------------------------------------------------------------------------------
[2023-05-03T11:50:02.650+0000] {taskinstance.py:1289} INFO - Starting attempt 1 of 1
[2023-05-03T11:50:02.651+0000] {taskinstance.py:1290} INFO - 
--------------------------------------------------------------------------------
[2023-05-03T11:50:02.660+0000] {taskinstance.py:1309} INFO - Executing <Task(PythonOperator): chatgpt_request> on 2023-05-03 11:45:00+00:00
[2023-05-03T11:50:02.663+0000] {standard_task_runner.py:55} INFO - Started process 188604 to run task
[2023-05-03T11:50:02.665+0000] {standard_task_runner.py:82} INFO - Running: ['airflow', 'tasks', 'run', 'chatgpt_dag', 'chatgpt_request', 'scheduled__2023-05-03T11:45:00+00:00', '--job-id', '2345', '--raw', '--subdir', 'DAGS_FOLDER/chatgpt_dag.py', '--cfg-path', '/tmp/tmpd1uff7cj']
[2023-05-03T11:50:02.665+0000] {standard_task_runner.py:83} INFO - Job 2345: Subtask chatgpt_request
[2023-05-03T11:50:02.694+0000] {task_command.py:389} INFO - Running <TaskInstance: chatgpt_dag.chatgpt_request scheduled__2023-05-03T11:45:00+00:00 [running]> on host trivia-machine.us-central1-a.c.triviapractice-381517.internal
[2023-05-03T11:50:02.732+0000] {taskinstance.py:1516} INFO - Exporting the following env vars:
AIRFLOW_CTX_DAG_OWNER=richc
AIRFLOW_CTX_DAG_ID=chatgpt_dag
AIRFLOW_CTX_TASK_ID=chatgpt_request
AIRFLOW_CTX_EXECUTION_DATE=2023-05-03T11:45:00+00:00
AIRFLOW_CTX_TRY_NUMBER=1
AIRFLOW_CTX_DAG_RUN_ID=scheduled__2023-05-03T11:45:00+00:00
[2023-05-03T11:50:02.964+0000] {util.py:67} INFO - error_code=None error_message='The server had an error while processing your request. Sorry about that!' error_param=None error_type=server_error message='OpenAI API error received' stream_error=False
[2023-05-03T11:50:02.965+0000] {taskinstance.py:1776} ERROR - Task failed with exception
Traceback (most recent call last):
  File "/usr/local/lib/python3.9/dist-packages/airflow/operators/python.py", line 175, in execute
    return_value = self.execute_callable()
  File "/usr/local/lib/python3.9/dist-packages/airflow/operators/python.py", line 192, in execute_callable
    return self.python_callable(*self.op_args, **self.op_kwargs)
  File "/home/rich2/airflow/dags/chatgpt_dag.py", line 40, in chatgpt_request
    response = openai.Completion.create(
  File "/home/rich2/.local/lib/python3.9/site-packages/openai/api_resources/completion.py", line 25, in create
    return super().create(*args, **kwargs)
  File "/home/rich2/.local/lib/python3.9/site-packages/openai/api_resources/abstract/engine_api_resource.py", line 153, in create
    response, _, api_key = requestor.request(
  File "/home/rich2/.local/lib/python3.9/site-packages/openai/api_requestor.py", line 226, in request
    resp, got_stream = self._interpret_response(result, stream)
  File "/home/rich2/.local/lib/python3.9/site-packages/openai/api_requestor.py", line 620, in _interpret_response
    self._interpret_response_line(
  File "/home/rich2/.local/lib/python3.9/site-packages/openai/api_requestor.py", line 683, in _interpret_response_line
    raise self.handle_error_response(
openai.error.RateLimitError: The server had an error while processing your request. Sorry about that!
[2023-05-03T11:50:02.968+0000] {taskinstance.py:1327} INFO - Marking task as FAILED. dag_id=chatgpt_dag, task_id=chatgpt_request, execution_date=20230503T114500, start_date=20230503T115002, end_date=20230503T115002
[2023-05-03T11:50:02.977+0000] {standard_task_runner.py:100} ERROR - Failed to execute job 2345 for task chatgpt_request (The server had an error while processing your request. Sorry about that!; 188604)
[2023-05-03T11:50:02.996+0000] {local_task_job.py:212} INFO - Task exited with return code 1
[2023-05-03T11:50:03.008+0000] {taskinstance.py:2596} INFO - 0 downstream tasks scheduled from follow-on schedule check
